File: 23년여름방학_화학공학랩실/분석자료파일/202030706_XRD_NiO/NiO_500C_v1.ras
*RAS_DATA_START
*RAS_HEADER_START
*DISP_FMT_X "%.2f"
*DISP_FMT_Y "%.0f"
*DISP_FULLSCALE "87951.0000000000"
*DISP_LINE_COLOR "255.0000000000"
*DISP_LINE_STYLE "0.0000000000"
*DISP_LINE_WIDTH "0.2500000000"
*DISP_NOTE "Collected Data-1"
*DISP_OFFSET_Y "0.0000000000"
*DISP_PEAKSEARCH_UNIT_Y "CPS"
*DISP_RANGE_BOTTOM "0.0000000000"
*DISP_RANGE_LEFT "20.0000000000"
*DISP_RANGE_LOGCUTOFF "0.0100000000"
*DISP_RANGE_RIGHT "80.0000000000"
*DISP_RANGE_TOP "87951.0000000000"
*DISP_SCALE_MODE_Y "0.0000000000"
*DISP_TAB_NAME "Theta/2-Theta"
*DISP_TITLE_Y "Intensity"
*DISP_UNIT_Y "CPS"
*DISP_WINDOW_NAME "MSG_MACROENGINE"
*FILE_COMMENT " "
*FILE_MD5 ""
*FILE_MEMO " "
*FILE_OPERATOR "crystal"
*FILE_PART_ID "MEAS_PBEA_00223"
*FILE_SAMPLE "NiO_500C_v1"
*FILE_TYPE "RAS_RAW"
*FILE_USERGROUP "System User"
*FILE_VERSION "1.0000000000"
*HW_ATTACHMENT_ID "ATT1031"
*HW_ATTACHMENT_NAME "6サンプルチェンジャ|ASC-6"
*HW_COUNTER_ID-0 "CUT0025"
*HW_COUNTER_ID-1 "CUT0020"
*HW_COUNTER_ID-2 "CUT0020"
*HW_COUNTER_ID-3 "CMC0021"
*HW_COUNTER_NAME-0 "D/teX Ultra|D/teX Ultra"
*HW_COUNTER_NAME-1 "None|None"
*HW_COUNTER_NAME-2 "None|None"
*HW_COUNTER_NAME-3 "検出器モノクロメータ|Detector monochromator"
*HW_COUNTER_SELECT_NAME "D/teX Ultra|D/teX Ultra"
*HW_GONIOMETER_ID "GON0070"
*HW_GONIOMETER_NAME "MiniFlex 300/600|MiniFlex 300/600"
*HW_GONIOMETER_RADIUS-0 "79.0"
*HW_GONIOMETER_RADIUS-1 "91.5"
*HW_GONIOMETER_RADIUS-2 "150.0"
*HW_GONIOMETER_RADIUS-3 "0"
*HW_GONIOMETER_RADIUS-4 "103.4"
*HW_GONIOMETER_RADIUS-5 "150.0"
*HW_GONIOMETER_RADIUS-6 "46.6"
*HW_GONIOMETER_RADIUS-7 "160.0"
*HW_I_OPT_ID-0 "ISL0021"
*HW_I_OPT_ID-1 "ISO0021"
*HW_I_OPT_NAME-0 "発散スリット|Divergence slit"
*HW_I_OPT_NAME-1 "入射平行スリット|Incident parallel slit"
*HW_R_ATTENUATER_AUTOMODE "0"
*HW_R_OPT_ID-0 "RSS0021"
*HW_R_OPT_ID-1 "RSO0021"
*HW_R_OPT_ID-2 "RRS0021"
*HW_R_OPT_NAME-0 "散乱スリット|Scattering slit"
*HW_R_OPT_NAME-1 "受光平行スリット|Receiving soller slit"
*HW_R_OPT_NAME-2 "受光スリット|Receiving slit"
*HW_SAMPLE_HOLDER_ID "SMP0000"
*HW_SAMPLE_HOLDER_NAME "無し|None"
*HW_XG_CURRENT_MAX "15"
*HW_XG_CURRENT_MIN "2"
*HW_XG_CURRENT_RESOLUTION "1"
*HW_XG_CURRENT_UNIT "mA"
*HW_XG_FOCUS "1mm x 10mm"
*HW_XG_FOCUS_TYPE "Normal"
*HW_XG_ID "1060"
*HW_XG_NAME "300W/600W 封入管-B|300W/600W Sealed tube-B"
*HW_XG_TARGET_ATOMIC_NUMBER "29.0000000000"
*HW_XG_TARGET_NAME "Cu"
*HW_XG_TYPE "Hermetic"
*HW_XG_VOLTAGE_MAX "40"
*HW_XG_VOLTAGE_MIN "20"
*HW_XG_VOLTAGE_RESOLUTION "1"
*HW_XG_VOLTAGE_UNIT "kV"
*HW_XG_WATT_MAX "1"
*HW_XG_WATT_UNIT "kW"
*HW_XG_WAVE_LENGTH_ALPHA1 "1.540593"
*HW_XG_WAVE_LENGTH_ALPHA2 "1.544414"
*HW_XG_WAVE_LENGTH_BETA "1.392250"
*MEAS_COND_AXIS_NAME-0 "Theta/2-Theta"
*MEAS_COND_AXIS_NAME-1 "Spin"
*MEAS_COND_AXIS_NAME-2 "Change"
*MEAS_COND_AXIS_NAME-3 "Soller(inc.)"
*MEAS_COND_AXIS_NAME-4 "IHS"
*MEAS_COND_AXIS_NAME-5 "DS"
*MEAS_COND_AXIS_NAME-6 "SS"
*MEAS_COND_AXIS_NAME-7 "Soller(rec.)"
*MEAS_COND_AXIS_NAME-8 "RS"
*MEAS_COND_AXIS_NAME-9 "Filter"
*MEAS_COND_AXIS_NAME-10 "Monochromator"
*MEAS_COND_AXIS_NAME-11 "PHA"
*MEAS_COND_AXIS_NAME_INTERNAL-0 "TwoThetaTheta"
*MEAS_COND_AXIS_NAME_INTERNAL-1 "Spin"
*MEAS_COND_AXIS_NAME_INTERNAL-2 "Change"
*MEAS_COND_AXIS_NAME_INTERNAL-3 "IncidentSollerSlit"
*MEAS_COND_AXIS_NAME_INTERNAL-4 "IncidentAxdSlit"
*MEAS_COND_AXIS_NAME_INTERNAL-5 "IncidentSlitBox"
*MEAS_COND_AXIS_NAME_INTERNAL-6 "ReceivingSlitBox1"
*MEAS_COND_AXIS_NAME_INTERNAL-7 "ReceivingSollerSlit"
*MEAS_COND_AXIS_NAME_INTERNAL-8 "ReceivingSlitBox2"
*MEAS_COND_AXIS_NAME_INTERNAL-9 "Filter"
*MEAS_COND_AXIS_NAME_INTERNAL-10 "CounterMonochromator"
*MEAS_COND_AXIS_NAME_INTERNAL-11 "PHA"
*MEAS_COND_AXIS_NAME_MAGICNO-0 "268632064.0000000000"
*MEAS_COND_AXIS_NAME_MAGICNO-1 "16842752.0000000000"
*MEAS_COND_AXIS_NAME_MAGICNO-2 "16842752.0000000000"
*MEAS_COND_AXIS_NAME_MAGICNO-3 "20971521.0000000000"
*MEAS_COND_AXIS_NAME_MAGICNO-4 "22020097.0000000000"
*MEAS_COND_AXIS_NAME_MAGICNO-5 "22020097.0000000000"
*MEAS_COND_AXIS_NAME_MAGICNO-6 "23068673.0000000000"
*MEAS_COND_AXIS_NAME_MAGICNO-7 "20971521.0000000000"
*MEAS_COND_AXIS_NAME_MAGICNO-8 "23068673.0000000000"
*MEAS_COND_AXIS_NAME_MAGICNO-9 "20971521.0000000000"
*MEAS_COND_AXIS_NAME_MAGICNO-10 "20971521.0000000000"
*MEAS_COND_AXIS_NAME_MAGICNO-11 "0.0000000000"
*MEAS_COND_AXIS_OFFSET-0 "0.0000000000"
*MEAS_COND_AXIS_OFFSET-1 "-"
*MEAS_COND_AXIS_OFFSET-2 "-"
*MEAS_COND_AXIS_OFFSET-3 "-"
*MEAS_COND_AXIS_OFFSET-4 "-"
*MEAS_COND_AXIS_OFFSET-5 "-"
*MEAS_COND_AXIS_OFFSET-6 "-"
*MEAS_COND_AXIS_OFFSET-7 "-"
*MEAS_COND_AXIS_OFFSET-8 "-"
*MEAS_COND_AXIS_OFFSET-9 "-"
*MEAS_COND_AXIS_OFFSET-10 "-"
*MEAS_COND_AXIS_OFFSET-11 "-"
*MEAS_COND_AXIS_POSITION-0 "12.0000000000"
*MEAS_COND_AXIS_POSITION-1 "0.0000000000"
*MEAS_COND_AXIS_POSITION-2 "4.0000000000"
*MEAS_COND_AXIS_POSITION-3 "5.0deg"
*MEAS_COND_AXIS_POSITION-4 "10.0mm"
*MEAS_COND_AXIS_POSITION-5 "1.250deg"
*MEAS_COND_AXIS_POSITION-6 "13.0mm(Open)"
*MEAS_COND_AXIS_POSITION-7 "5.0deg"
*MEAS_COND_AXIS_POSITION-8 "13.0mm"
*MEAS_COND_AXIS_POSITION-9 "None"
*MEAS_COND_AXIS_POSITION-10 "None"
*MEAS_COND_AXIS_POSITION-11 "35.0000000000"
*MEAS_COND_AXIS_UNIT-0 "deg"
*MEAS_COND_AXIS_UNIT-1 ""
*MEAS_COND_AXIS_UNIT-2 ""
*MEAS_COND_AXIS_UNIT-3 ""
*MEAS_COND_AXIS_UNIT-4 ""
*MEAS_COND_AXIS_UNIT-5 ""
*MEAS_COND_AXIS_UNIT-6 ""
*MEAS_COND_AXIS_UNIT-7 ""
*MEAS_COND_AXIS_UNIT-8 ""
*MEAS_COND_AXIS_UNIT-9 ""
*MEAS_COND_AXIS_UNIT-10 ""
*MEAS_COND_AXIS_UNIT-11 "div"
*MEAS_COND_COUNTER_CNTLOSS_CORR "0.0000000000"
*MEAS_COND_COUNTER_PHABASE "35.0000000000"
*MEAS_COND_COUNTER_PHAWINDOW "15.0000000000"
*MEAS_COND_COUNTER_PHA_UNIT "div"
*MEAS_COND_COUNTER_TAUDIFF "0.2500000000"
*MEAS_COND_COUNTER_TAUINT "0.7500000000"
*MEAS_COND_IRRADIATION_MODE "OFF"
*MEAS_COND_IRRADIATION_WIDTH ""
*MEAS_COND_OPT_ATTR " "
*MEAS_COND_OPT_NAME ""
*MEAS_COND_UNSYMMETRIC_MODE "OFF"
*MEAS_COND_XG_CURRENT "15.0000000000"
*MEAS_COND_XG_VOLTAGE "40.0000000000"
*MEAS_COND_XG_WAVE_TYPE "Ka"
*MEAS_DATA_COUNT "3001.0000000000"
*MEAS_SCAN_AXIS_X "Theta/2-Theta"
*MEAS_SCAN_AXIS_X_INTERNAL "TwoThetaTheta"
*MEAS_SCAN_END_TIME "07/04/23 17:12:17"
*MEAS_SCAN_MODE "CONTINUOUS"
*MEAS_SCAN_MONITOR "0"
*MEAS_SCAN_RESOLUTION_X "0.005"
*MEAS_SCAN_SPEED "1.500"
*MEAS_SCAN_SPEED_UNIT "deg/min"
*MEAS_SCAN_SPEED_USER "1.500"
*MEAS_SCAN_START "20.0000000000"
*MEAS_SCAN_START_TIME "07/04/23 16:28:43"
*MEAS_SCAN_STEP "0.0200000000"
*MEAS_SCAN_STOP "80.0000000000"
*MEAS_SCAN_UNIT_X "deg"
*MEAS_SCAN_UNIT_Y "counts"
*SLIT_SYSTEM "0"
*RAS_HEADER_END
*RAS_INT_START
20.000 5788.000 1.000
20.060 5932.000 1.000
20.120 5939.000 1.000
20.180 5960.000 1.000
20.240 6026.000 1.000
20.300 6028.000 1.000
20.360 5985.000 1.000
20.420 5923.000 1.000
20.480 6086.000 1.000
20.540 5995.000 1.000
20.600 5997.000 1.000
20.660 5997.000 1.000
20.720 5942.000 1.000
20.780 5963.000 1.000
20.840 6014.000 1.000
20.900 5965.000 1.000
20.960 6026.000 1.000
21.020 6080.000 1.000
21.080 5921.000 1.000
21.140 5978.000 1.000
21.200 6032.000 1.000
21.260 6142.000 1.000
21.320 6017.000 1.000
21.380 6293.000 1.000
21.440 6051.000 1.000
21.500 6144.000 1.000
21.560 6143.000 1.000
21.620 6201.000 1.000
21.680 6129.000 1.000
21.740 6166.000 1.000
21.800 6088.000 1.000
21.860 6168.000 1.000
21.920 6150.000 1.000
21.980 6372.000 1.000
22.040 6140.000 1.000
22.100 6143.000 1.000
22.160 6316.000 1.000
22.220 6213.000 1.000
22.280 6138.000 1.000
22.340 6150.000 1.000
22.400 6189.000 1.000
22.460 6219.000 1.000
22.520 6202.000 1.000
22.580 6226.000 1.000
22.640 6212.000 1.000
22.700 6117.000 1.000
22.760 6224.000 1.000
22.820 6227.000 1.000
22.880 6130.000 1.000
22.940 6216.000 1.000
23.000 6178.000 1.000
23.060 6233.000 1.000
23.120 6283.000 1.000
23.180 6173.000 1.000
23.240 6179.000 1.000
23.300 6300.000 1.000
23.360 6197.000 1.000
23.420 6264.000 1.000
23.480 6281.000 1.000
23.540 6145.000 1.000
23.600 6259.000 1.000
23.660 6382.000 1.000
23.720 6280.000 1.000
23.780 6268.000 1.000
23.840 6244.000 1.000
23.900 6258.000 1.000
23.960 6236.000 1.000
24.020 6203.000 1.000
24.080 6264.000 1.000
24.140 6197.000 1.000
24.200 6189.000 1.000
24.260 6317.000 1.000
24.320 6381.000 1.000
24.380 6323.000 1.000
24.440 6377.000 1.000
24.500 6164.000 1.000
24.560 6353.000 1.000
24.620 6187.000 1.000
24.680 6147.000 1.000
24.740 6249.000 1.000
24.800 6319.000 1.000
24.860 6433.000 1.000
24.920 6277.000 1.000
24.980 6322.000 1.000
25.040 6389.000 1.000
25.100 6288.000 1.000
25.160 6229.000 1.000
25.220 6406.000 1.000
25.280 6219.000 1.000
25.340 6237.000 1.000
25.400 6223.000 1.000
25.460 6382.000 1.000
25.520 6229.000 1.000
25.580 6315.000 1.000
25.640 6258.000 1.000
25.700 6259.000 1.000
25.760 6294.000 1.000
25.820 6326.000 1.000
25.880 6243.000 1.000
25.940 6256.000 1.000
26.000 6348.000 1.000
26.060 6449.000 1.000
26.120 6477.000 1.000
26.180 6293.000 1.000
26.240 6397.000 1.000
26.300 6194.000 1.000
26.360 6332.000 1.000
26.420 6369.000 1.000
26.480 6274.000 1.000
26.540 6391.000 1.000
26.600 6269.000 1.000
26.660 6179.000 1.000
26.720 6388.000 1.000
26.780 6430.000 1.000
26.840 6191.000 1.000
26.900 6278.000 1.000
26.960 6235.000 1.000
27.020 6363.000 1.000
27.080 6314.000 1.000
27.140 6267.000 1.000
27.200 6432.000 1.000
27.260 6314.000 1.000
27.320 6345.000 1.000
27.380 6181.000 1.000
27.440 6341.000 1.000
27.500 6398.000 1.000
27.560 6334.000 1.000
27.620 6309.000 1.000
27.680 6346.000 1.000
27.740 6304.000 1.000
27.800 6314.000 1.000
27.860 6373.000 1.000
27.920 6329.000 1.000
27.980 6363.000 1.000
28.040 6334.000 1.000
28.100 6392.000 1.000
28.160 6252.000 1.000
28.220 6268.000 1.000
28.280 6414.000 1.000
28.340 6355.000 1.000
28.400 6273.000 1.000
28.460 6413.000 1.000
28.520 6373.000 1.000
28.580 6315.000 1.000
28.640 6291.000 1.000
28.700 6214.000 1.000
28.760 6314.000 1.000
28.820 6261.000 1.000
28.880 6345.000 1.000
28.940 6407.000 1.000
29.000 6327.000 1.000
29.060 6247.000 1.000
29.120 6327.000 1.000
29.180 6308.000 1.000
29.240 6244.000 1.000
29.300 6378.000 1.000
29.360 6375.000 1.000
29.420 6348.000 1.000
29.480 6288.000 1.000
29.540 6318.000 1.000
29.600 6320.000 1.000
29.660 6358.000 1.000
29.720 6406.000 1.000
29.780 6250.000 1.000
29.840 6443.000 1.000
29.900 6212.000 1.000
29.960 6262.000 1.000
30.020 6391.000 1.000
30.080 6279.000 1.000
30.140 6279.000 1.000
30.200 6296.000 1.000
30.260 6394.000 1.000
30.320 6379.000 1.000
30.380 6323.000 1.000
30.440 6312.000 1.000
30.500 6264.000 1.000
30.560 6211.000 1.000
30.620 6274.000 1.000
30.680 6319.000 1.000
30.740 6390.000 1.000
30.800 6315.000 1.000
30.860 6381.000 1.000
30.920 6398.000 1.000
30.980 6188.000 1.000
31.040 6450.000 1.000
31.100 6190.000 1.000
31.160 6387.000 1.000
31.220 6350.000 1.000
31.280 6294.000 1.000
31.340 6200.000 1.000
31.400 6386.000 1.000
31.460 6343.000 1.000
31.520 6336.000 1.000
31.580 6255.000 1.000
31.640 6499.000 1.000
31.700 6381.000 1.000
31.760 6257.000 1.000
31.820 6245.000 1.000
31.880 6362.000 1.000
31.940 6314.000 1.000
32.000 6350.000 1.000
32.060 6344.000 1.000
32.120 6390.000 1.000
32.180 6345.000 1.000
32.240 6292.000 1.000
32.300 6324.000 1.000
32.360 6315.000 1.000
32.420 6354.000 1.000
32.480 6436.000 1.000
32.540 6264.000 1.000
32.600 6337.000 1.000
32.660 6333.000 1.000
32.720 6332.000 1.000
32.780 6373.000 1.000
32.840 6278.000 1.000
32.900 6426.000 1.000
32.960 6299.000 1.000
33.020 6252.000 1.000
33.080 6409.000 1.000
33.140 6327.000 1.000
33.200 6230.000 1.000
33.260 6418.000 1.000
33.320 6390.000 1.000
33.380 6431.000 1.000
33.440 6476.000 1.000
33.500 6478.000 1.000
33.560 6398.000 1.000
33.620 6291.000 1.000
33.680 6463.000 1.000
33.740 6367.000 1.000
33.800 6331.000 1.000
33.860 6476.000 1.000
33.920 6400.000 1.000
33.980 6396.000 1.000
34.040 6420.000 1.000
34.100 6493.000 1.000
34.160 6240.000 1.000
34.220 6464.000 1.000
34.280 6457.000 1.000
34.340 6409.000 1.000
34.400 6367.000 1.000
34.460 6371.000 1.000
34.520 6333.000 1.000
34.580 6398.000 1.000
34.640 6310.000 1.000
34.700 6345.000 1.000
34.760 6505.000 1.000
34.820 6561.000 1.000
34.880 6494.000 1.000
34.940 6327.000 1.000
35.000 6455.000 1.000
35.060 6526.000 1.000
35.120 6557.000 1.000
35.180 6604.000 1.000
35.240 6470.000 1.000
35.300 6464.000 1.000
35.360 6582.000 1.000
35.420 6419.000 1.000
35.480 6472.000 1.000
35.540 6523.000 1.000
35.600 6576.000 1.000
35.660 6703.000 1.000
35.720 6532.000 1.000
35.780 6703.000 1.000
35.840 6745.000 1.000
35.900 6922.000 1.000
35.960 6746.000 1.000
36.020 6878.000 1.000
36.080 6888.000 1.000
36.140 6935.000 1.000
36.200 6921.000 1.000
36.260 7272.000 1.000
36.320 7098.000 1.000
36.380 7360.000 1.000
36.440 7557.000 1.000
36.500 7680.000 1.000
36.560 7881.000 1.000
36.620 8290.000 1.000
36.680 8802.000 1.000
36.740 9591.000 1.000
36.800 10343.000 1.000
36.860 11378.000 1.000
36.920 13157.000 1.000
36.980 15686.000 1.000
37.040 19207.000 1.000
37.100 24631.000 1.000
37.160 31315.000 1.000
37.220 38458.000 1.000
37.280 39961.000 1.000
37.340 35391.000 1.000
37.400 27657.000 1.000
37.460 20918.000 1.000
37.520 16180.000 1.000
37.580 13175.000 1.000
37.640 10990.000 1.000
37.700 9654.000 1.000
37.760 8835.000 1.000
37.820 8253.000 1.000
37.880 7906.000 1.000
37.940 7594.000 1.000
38.000 7432.000 1.000
38.060 7257.000 1.000
38.120 7133.000 1.000
38.180 7299.000 1.000
38.240 6972.000 1.000
38.300 6864.000 1.000
38.360 6905.000 1.000
38.420 6729.000 1.000
38.480 6832.000 1.000
38.540 6604.000 1.000
38.600 6801.000 1.000
38.660 6690.000 1.000
38.720 6751.000 1.000
38.780 6709.000 1.000
38.840 6878.000 1.000
38.900 6444.000 1.000
38.960 6560.000 1.000
39.020 6587.000 1.000
39.080 6442.000 1.000
39.140 6670.000 1.000
39.200 6512.000 1.000
39.260 6559.000 1.000
39.320 6405.000 1.000
39.380 6581.000 1.000
39.440 6633.000 1.000
39.500 6565.000 1.000
39.560 6465.000 1.000
39.620 6465.000 1.000
39.680 6421.000 1.000
39.740 6398.000 1.000
39.800 6500.000 1.000
39.860 6528.000 1.000
39.920 6454.000 1.000
39.980 6534.000 1.000
40.040 6360.000 1.000
40.100 6543.000 1.000
40.160 6521.000 1.000
40.220 6424.000 1.000
40.280 6448.000 1.000
40.340 6581.000 1.000
40.400 6440.000 1.000
40.460 6466.000 1.000
40.520 6530.000 1.000
40.580 6531.000 1.000
40.640 6481.000 1.000
40.700 6442.000 1.000
40.760 6537.000 1.000
40.820 6501.000 1.000
40.880 6481.000 1.000
40.940 6521.000 1.000
41.000 6470.000 1.000
41.060 6490.000 1.000
41.120 6463.000 1.000
41.180 6523.000 1.000
41.240 6747.000 1.000
41.300 6669.000 1.000
41.360 6482.000 1.000
41.420 6669.000 1.000
41.480 6756.000 1.000
41.540 6769.000 1.000
41.600 6790.000 1.000
41.660 6714.000 1.000
41.720 6810.000 1.000
41.780 6835.000 1.000
41.840 7013.000 1.000
41.900 6971.000 1.000
41.960 7104.000 1.000
42.020 7144.000 1.000
42.080 7220.000 1.000
42.140 7339.000 1.000
42.200 7276.000 1.000
42.260 7494.000 1.000
42.320 7759.000 1.000
42.380 7777.000 1.000
42.440 8042.000 1.000
42.500 8427.000 1.000
42.560 8720.000 1.000
42.620 9161.000 1.000
42.680 9830.000 1.000
42.740 10640.000 1.000
42.800 11988.000 1.000
42.860 13541.000 1.000
42.920 15781.000 1.000
42.980 18695.000 1.000
43.040 23143.000 1.000
43.100 29506.000 1.000
43.160 39015.000 1.000
43.220 50200.000 1.000
43.280 58236.000 1.000
43.340 56592.000 1.000
43.400 47652.000 1.000
43.460 36998.000 1.000
43.520 27469.000 1.000
43.580 21156.000 1.000
43.640 16314.000 1.000
43.700 14026.000 1.000
43.760 11910.000 1.000
43.820 10615.000 1.000
43.880 9747.000 1.000
43.940 9072.000 1.000
44.000 8669.000 1.000
44.060 8292.000 1.000
44.120 8005.000 1.000
44.180 7718.000 1.000
44.240 7448.000 1.000
44.300 7439.000 1.000
44.360 7325.000 1.000
44.420 7222.000 1.000
44.480 7208.000 1.000
44.540 7053.000 1.000
44.600 7120.000 1.000
44.660 6873.000 1.000
44.720 6936.000 1.000
44.780 6850.000 1.000
44.840 6821.000 1.000
44.900 6890.000 1.000
44.960 6806.000 1.000
45.020 6719.000 1.000
45.080 6822.000 1.000
45.140 6677.000 1.000
45.200 6579.000 1.000
45.260 6711.000 1.000
45.320 6608.000 1.000
45.380 6458.000 1.000
45.440 6506.000 1.000
45.500 6547.000 1.000
45.560 6563.000 1.000
45.620 6589.000 1.000
45.680 6538.000 1.000
45.740 6590.000 1.000
45.800 6554.000 1.000
45.860 6553.000 1.000
45.920 6450.000 1.000
45.980 6472.000 1.000
46.040 6550.000 1.000
46.100 6527.000 1.000
46.160 6558.000 1.000
46.220 6492.000 1.000
46.280 6615.000 1.000
46.340 6456.000 1.000
46.400 6419.000 1.000
46.460 6498.000 1.000
46.520 6376.000 1.000
46.580 6508.000 1.000
46.640 6453.000 1.000
46.700 6434.000 1.000
46.760 6617.000 1.000
46.820 6432.000 1.000
46.880 6434.000 1.000
46.940 6433.000 1.000
47.000 6405.000 1.000
47.060 6250.000 1.000
47.120 6385.000 1.000
47.180 6413.000 1.000
47.240 6363.000 1.000
47.300 6406.000 1.000
47.360 6286.000 1.000
47.420 6433.000 1.000
47.480 6424.000 1.000
47.540 6461.000 1.000
47.600 6283.000 1.000
47.660 6412.000 1.000
47.720 6323.000 1.000
47.780 6306.000 1.000
47.840 6280.000 1.000
47.900 6249.000 1.000
47.960 6291.000 1.000
48.020 6404.000 1.000
48.080 6271.000 1.000
48.140 6420.000 1.000
48.200 6402.000 1.000
48.260 6277.000 1.000
48.320 6330.000 1.000
48.380 6291.000 1.000
48.440 6265.000 1.000
48.500 6251.000 1.000
48.560 6503.000 1.000
48.620 6199.000 1.000
48.680 6344.000 1.000
48.740 6049.000 1.000
48.800 6222.000 1.000
48.860 6197.000 1.000
48.920 6267.000 1.000
48.980 6227.000 1.000
49.040 6318.000 1.000
49.100 6285.000 1.000
49.160 6371.000 1.000
49.220 6101.000 1.000
49.280 6300.000 1.000
49.340 6305.000 1.000
49.400 6309.000 1.000
49.460 6111.000 1.000
49.520 6357.000 1.000
49.580 6262.000 1.000
49.640 6301.000 1.000
49.700 6442.000 1.000
49.760 6312.000 1.000
49.820 6146.000 1.000
49.880 6241.000 1.000
49.940 6313.000 1.000
50.000 6285.000 1.000
50.060 6293.000 1.000
50.120 6205.000 1.000
50.180 6299.000 1.000
50.240 6185.000 1.000
50.300 6315.000 1.000
50.360 6260.000 1.000
50.420 6400.000 1.000
50.480 6253.000 1.000
50.540 6266.000 1.000
50.600 6344.000 1.000
50.660 6247.000 1.000
50.720 6336.000 1.000
50.780 6312.000 1.000
50.840 6271.000 1.000
50.900 6343.000 1.000
50.960 6314.000 1.000
51.020 6152.000 1.000
51.080 6204.000 1.000
51.140 6236.000 1.000
51.200 6298.000 1.000
51.260 6338.000 1.000
51.320 6254.000 1.000
51.380 6145.000 1.000
51.440 6333.000 1.000
51.500 6211.000 1.000
51.560 6278.000 1.000
51.620 6328.000 1.000
51.680 6266.000 1.000
51.740 6260.000 1.000
51.800 6282.000 1.000
51.860 6109.000 1.000
51.920 6113.000 1.000
51.980 6161.000 1.000
52.040 6332.000 1.000
52.100 6190.000 1.000
52.160 6326.000 1.000
52.220 6168.000 1.000
52.280 6242.000 1.000
52.340 6273.000 1.000
52.400 6238.000 1.000
52.460 6196.000 1.000
52.520 6114.000 1.000
52.580 6112.000 1.000
52.640 6287.000 1.000
52.700 6170.000 1.000
52.760 6219.000 1.000
52.820 6241.000 1.000
52.880 6181.000 1.000
52.940 6131.000 1.000
53.000 6159.000 1.000
53.060 6241.000 1.000
53.120 6322.000 1.000
53.180 6208.000 1.000
53.240 6199.000 1.000
53.300 6235.000 1.000
53.360 6259.000 1.000
53.420 6204.000 1.000
53.480 6204.000 1.000
53.540 6200.000 1.000
53.600 6107.000 1.000
53.660 6267.000 1.000
53.720 6130.000 1.000
53.780 6075.000 1.000
53.840 6213.000 1.000
53.900 6234.000 1.000
53.960 6229.000 1.000
54.020 6247.000 1.000
54.080 6237.000 1.000
54.140 6303.000 1.000
54.200 6154.000 1.000
54.260 6216.000 1.000
54.320 6171.000 1.000
54.380 6228.000 1.000
54.440 6210.000 1.000
54.500 6119.000 1.000
54.560 6186.000 1.000
54.620 6179.000 1.000
54.680 6145.000 1.000
54.740 6077.000 1.000
54.800 6328.000 1.000
54.860 6238.000 1.000
54.920 6110.000 1.000
54.980 6364.000 1.000
55.040 6188.000 1.000
55.100 6165.000 1.000
55.160 6144.000 1.000
55.220 6225.000 1.000
55.280 6240.000 1.000
55.340 6139.000 1.000
55.400 6110.000 1.000
55.460 6325.000 1.000
55.520 6194.000 1.000
55.580 6347.000 1.000
55.640 6226.000 1.000
55.700 6221.000 1.000
55.760 6164.000 1.000
55.820 6148.000 1.000
55.880 6169.000 1.000
55.940 6233.000 1.000
56.000 6241.000 1.000
56.060 6217.000 1.000
56.120 6131.000 1.000
56.180 6210.000 1.000
56.240 6274.000 1.000
56.300 6191.000 1.000
56.360 6269.000 1.000
56.420 6187.000 1.000
56.480 6113.000 1.000
56.540 6302.000 1.000
56.600 6305.000 1.000
56.660 6162.000 1.000
56.720 6209.000 1.000
56.780 6169.000 1.000
56.840 6230.000 1.000
56.900 6292.000 1.000
56.960 6217.000 1.000
57.020 6124.000 1.000
57.080 6243.000 1.000
57.140 6160.000 1.000
57.200 6158.000 1.000
57.260 6134.000 1.000
57.320 6146.000 1.000
57.380 6164.000 1.000
57.440 6289.000 1.000
57.500 6106.000 1.000
57.560 6175.000 1.000
57.620 6181.000 1.000
57.680 6217.000 1.000
57.740 6228.000 1.000
57.800 6191.000 1.000
57.860 6228.000 1.000
57.920 6246.000 1.000
57.980 6258.000 1.000
58.040 6084.000 1.000
58.100 6177.000 1.000
58.160 6171.000 1.000
58.220 6299.000 1.000
58.280 6174.000 1.000
58.340 6216.000 1.000
58.400 6233.000 1.000
58.460 6121.000 1.000
58.520 6052.000 1.000
58.580 6244.000 1.000
58.640 6218.000 1.000
58.700 6166.000 1.000
58.760 6254.000 1.000
58.820 6167.000 1.000
58.880 6156.000 1.000
58.940 6204.000 1.000
59.000 6199.000 1.000
59.060 6242.000 1.000
59.120 6221.000 1.000
59.180 6034.000 1.000
59.240 6102.000 1.000
59.300 6177.000 1.000
59.360 6304.000 1.000
59.420 6209.000 1.000
59.480 6274.000 1.000
59.540 6091.000 1.000
59.600 6209.000 1.000
59.660 6167.000 1.000
59.720 6261.000 1.000
59.780 6294.000 1.000
59.840 6158.000 1.000
59.900 6213.000 1.000
59.960 6130.000 1.000
60.020 6203.000 1.000
60.080 6265.000 1.000
60.140 6235.000 1.000
60.200 6284.000 1.000
60.260 6288.000 1.000
60.320 6191.000 1.000
60.380 6284.000 1.000
60.440 6290.000 1.000
60.500 6316.000 1.000
60.560 6475.000 1.000
60.620 6302.000 1.000
60.680 6439.000 1.000
60.740 6237.000 1.000
60.800 6413.000 1.000
60.860 6413.000 1.000
60.920 6328.000 1.000
60.980 6329.000 1.000
61.040 6287.000 1.000
61.100 6404.000 1.000
61.160 6433.000 1.000
61.220 6381.000 1.000
61.280 6428.000 1.000
61.340 6460.000 1.000
61.400 6471.000 1.000
61.460 6507.000 1.000
61.520 6504.000 1.000
61.580 6519.000 1.000
61.640 6620.000 1.000
61.700 6774.000 1.000
61.760 6792.000 1.000
61.820 6787.000 1.000
61.880 6975.000 1.000
61.940 7037.000 1.000
62.000 7190.000 1.000
62.060 7278.000 1.000
62.120 7562.000 1.000
62.180 7782.000 1.000
62.240 8076.000 1.000
62.300 8462.000 1.000
62.360 9185.000 1.000
62.420 9979.000 1.000
62.480 10992.000 1.000
62.540 12546.000 1.000
62.600 14188.000 1.000
62.660 16889.000 1.000
62.720 20035.000 1.000
62.780 23499.000 1.000
62.840 26292.000 1.000
62.900 26840.000 1.000
62.960 25366.000 1.000
63.020 22993.000 1.000
63.080 20062.000 1.000
63.140 16827.000 1.000
63.200 13928.000 1.000
63.260 11897.000 1.000
63.320 10429.000 1.000
63.380 9581.000 1.000
63.440 8725.000 1.000
63.500 8265.000 1.000
63.560 7850.000 1.000
63.620 7404.000 1.000
63.680 7322.000 1.000
63.740 7062.000 1.000
63.800 6863.000 1.000
63.860 6866.000 1.000
63.920 6838.000 1.000
63.980 6693.000 1.000
64.040 6653.000 1.000
64.100 6512.000 1.000
64.160 6551.000 1.000
64.220 6460.000 1.000
64.280 6480.000 1.000
64.340 6584.000 1.000
64.400 6434.000 1.000
64.460 6453.000 1.000
64.520 6381.000 1.000
64.580 6295.000 1.000
64.640 6361.000 1.000
64.700 6444.000 1.000
64.760 6374.000 1.000
64.820 6336.000 1.000
64.880 6303.000 1.000
64.940 6393.000 1.000
65.000 6439.000 1.000
65.060 6371.000 1.000
65.120 6317.000 1.000
65.180 6315.000 1.000
65.240 6270.000 1.000
65.300 6434.000 1.000
65.360 6246.000 1.000
65.420 6333.000 1.000
65.480 6339.000 1.000
65.540 6335.000 1.000
65.600 6394.000 1.000
65.660 6300.000 1.000
65.720 6180.000 1.000
65.780 6225.000 1.000
65.840 6308.000 1.000
65.900 6328.000 1.000
65.960 6336.000 1.000
66.020 6314.000 1.000
66.080 6238.000 1.000
66.140 6234.000 1.000
66.200 6304.000 1.000
66.260 6224.000 1.000
66.320 6348.000 1.000
66.380 6209.000 1.000
66.440 6279.000 1.000
66.500 6313.000 1.000
66.560 6234.000 1.000
66.620 6305.000 1.000
66.680 6117.000 1.000
66.740 6167.000 1.000
66.800 6221.000 1.000
66.860 6245.000 1.000
66.920 6132.000 1.000
66.980 6202.000 1.000
67.040 6204.000 1.000
67.100 6333.000 1.000
67.160 6202.000 1.000
67.220 6259.000 1.000
67.280 6113.000 1.000
67.340 6229.000 1.000
67.400 6207.000 1.000
67.460 6173.000 1.000
67.520 6216.000 1.000
67.580 6281.000 1.000
67.640 6229.000 1.000
67.700 6126.000 1.000
67.760 6194.000 1.000
67.820 6259.000 1.000
67.880 6261.000 1.000
67.940 6199.000 1.000
68.000 6101.000 1.000
68.060 6302.000 1.000
68.120 6236.000 1.000
68.180 6258.000 1.000
68.240 6105.000 1.000
68.300 6245.000 1.000
68.360 6228.000 1.000
68.420 6173.000 1.000
68.480 6217.000 1.000
68.540 6113.000 1.000
68.600 6153.000 1.000
68.660 6137.000 1.000
68.720 6118.000 1.000
68.780 6240.000 1.000
68.840 6249.000 1.000
68.900 6124.000 1.000
68.960 6224.000 1.000
69.020 6204.000 1.000
69.080 6193.000 1.000
69.140 6137.000 1.000
69.200 6088.000 1.000
69.260 6163.000 1.000
69.320 6211.000 1.000
69.380 6271.000 1.000
69.440 6205.000 1.000
69.500 6170.000 1.000
69.560 6316.000 1.000
69.620 6145.000 1.000
69.680 6109.000 1.000
69.740 6219.000 1.000
69.800 6162.000 1.000
69.860 6175.000 1.000
69.920 6284.000 1.000
69.980 6193.000 1.000
70.040 6138.000 1.000
70.100 6169.000 1.000
70.160 6185.000 1.000
70.220 6155.000 1.000
70.280 6175.000 1.000
70.340 6278.000 1.000
70.400 6315.000 1.000
70.460 6187.000 1.000
70.520 6207.000 1.000
70.580 6156.000 1.000
70.640 6212.000 1.000
70.700 6310.000 1.000
70.760 6181.000 1.000
70.820 6044.000 1.000
70.880 6253.000 1.000
70.940 6222.000 1.000
71.000 6146.000 1.000
71.060 6092.000 1.000
71.120 6186.000 1.000
71.180 6329.000 1.000
71.240 6052.000 1.000
71.300 6223.000 1.000
71.360 6177.000 1.000
71.420 6245.000 1.000
71.480 6215.000 1.000
71.540 6030.000 1.000
71.600 6063.000 1.000
71.660 6124.000 1.000
71.720 6203.000 1.000
71.780 6337.000 1.000
71.840 6196.000 1.000
71.900 6192.000 1.000
71.960 6223.000 1.000
72.020 6090.000 1.000
72.080 6199.000 1.000
72.140 6246.000 1.000
72.200 6097.000 1.000
72.260 6228.000 1.000
72.320 6290.000 1.000
72.380 6241.000 1.000
72.440 6111.000 1.000
72.500 6122.000 1.000
72.560 6206.000 1.000
72.620 6284.000 1.000
72.680 6067.000 1.000
72.740 6067.000 1.000
72.800 6209.000 1.000
72.860 6082.000 1.000
72.920 6226.000 1.000
72.980 6153.000 1.000
73.040 6266.000 1.000
73.100 6197.000 1.000
73.160 6239.000 1.000
73.220 6256.000 1.000
73.280 6341.000 1.000
73.340 6204.000 1.000
73.400 6202.000 1.000
73.460 6143.000 1.000
73.520 6248.000 1.000
73.580 6213.000 1.000
73.640 6184.000 1.000
73.700 6352.000 1.000
73.760 6343.000 1.000
73.820 6143.000 1.000
73.880 6344.000 1.000
73.940 6225.000 1.000
74.000 6448.000 1.000
74.060 6415.000 1.000
74.120 6310.000 1.000
74.180 6432.000 1.000
74.240 6347.000 1.000
74.300 6365.000 1.000
74.360 6457.000 1.000
74.420 6465.000 1.000
74.480 6504.000 1.000
74.540 6572.000 1.000
74.600 6664.000 1.000
74.660 6719.000 1.000
74.720 6634.000 1.000
74.780 7064.000 1.000
74.840 7191.000 1.000
74.900 7420.000 1.000
74.960 7779.000 1.000
75.020 8050.000 1.000
75.080 8583.000 1.000
75.140 9303.000 1.000
75.200 10354.000 1.000
75.260 11142.000 1.000
75.320 12389.000 1.000
75.380 12796.000 1.000
75.440 13019.000 1.000
75.500 12502.000 1.000
75.560 11853.000 1.000
75.620 11146.000 1.000
75.680 10424.000 1.000
75.740 9320.000 1.000
75.800 8643.000 1.000
75.860 8056.000 1.000
75.920 7514.000 1.000
75.980 7218.000 1.000
76.040 6975.000 1.000
76.100 6833.000 1.000
76.160 6721.000 1.000
76.220 6839.000 1.000
76.280 6598.000 1.000
76.340 6531.000 1.000
76.400 6365.000 1.000
76.460 6548.000 1.000
76.520 6425.000 1.000
76.580 6495.000 1.000
76.640 6436.000 1.000
76.700 6325.000 1.000
76.760 6293.000 1.000
76.820 6280.000 1.000
76.880 6366.000 1.000
76.940 6251.000 1.000
77.000 6190.000 1.000
77.060 6269.000 1.000
77.120 6250.000 1.000
77.180 6213.000 1.000
77.240 6278.000 1.000
77.300 6327.000 1.000
77.360 6219.000 1.000
77.420 6139.000 1.000
77.480 6377.000 1.000
77.540 6219.000 1.000
77.600 6283.000 1.000
77.660 6165.000 1.000
77.720 6291.000 1.000
77.780 6281.000 1.000
77.840 6236.000 1.000
77.900 6241.000 1.000
77.960 6244.000 1.000
78.020 6328.000 1.000
78.080 6373.000 1.000
78.140 6228.000 1.000
78.200 6315.000 1.000
78.260 6420.000 1.000
78.320 6565.000 1.000
78.380 6383.000 1.000
78.440 6528.000 1.000
78.500 6412.000 1.000
78.560 6536.000 1.000
78.620 6437.000 1.000
78.680 6579.000 1.000
78.740 6669.000 1.000
78.800 6906.000 1.000
78.860 6999.000 1.000
78.920 7100.000 1.000
78.980 7486.000 1.000
79.040 7798.000 1.000
79.100 8258.000 1.000
79.160 8750.000 1.000
79.220 9472.000 1.000
79.280 10215.000 1.000
79.340 10716.000 1.000
79.400 10839.000 1.000
79.460 10731.000 1.000
79.520 10437.000 1.000
79.580 9849.000 1.000
79.640 9573.000 1.000
79.700 8982.000 1.000
79.760 8310.000 1.000
79.820 7822.000 1.000
79.880 7550.000 1.000
79.940 7316.000 1.000
80.000 6969.000 1.000
*RAS_INT_END
*RAS_DATA_END